// function errFunc() {
//   throw new Error('something went wrong')
// }
// try {
//   errFunc()
// } catch (error) {
//   console.log(error.message)
// }
// console.log('continue...')

// const test = (a) => {
//   console.log(a)
// }

// try {
//   test(let)
// } catch (error) {
//   console.log(error.message)
// }
// console.log('continue')
